[2025-08-19T19:56:48.295+0000] {local_task_job_runner.py:120} INFO - ::group::Pre task execution logs
[2025-08-19T19:56:48.423+0000] {taskinstance.py:2076} INFO - Dependencies all met for dep_context=non-requeueable deps ti=<TaskInstance: etl_pipeline.transform_data manual__2025-08-19T19:56:32.538640+00:00 [queued]>
[2025-08-19T19:56:48.447+0000] {taskinstance.py:2076} INFO - Dependencies all met for dep_context=requeueable deps ti=<TaskInstance: etl_pipeline.transform_data manual__2025-08-19T19:56:32.538640+00:00 [queued]>
[2025-08-19T19:56:48.448+0000] {taskinstance.py:2306} INFO - Starting attempt 1 of 1
[2025-08-19T19:56:48.487+0000] {taskinstance.py:2330} INFO - Executing <Task(PythonOperator): transform_data> on 2025-08-19 19:56:32.538640+00:00
[2025-08-19T19:56:48.515+0000] {logging_mixin.py:188} WARNING - /home/***/.local/lib/python3.12/site-packages/***/task/task_runner/standard_task_runner.py:62 DeprecationWarning: This process (pid=248) is multi-threaded, use of fork() may lead to deadlocks in the child.
[2025-08-19T19:56:48.526+0000] {standard_task_runner.py:64} INFO - Started process 250 to run task
[2025-08-19T19:56:48.533+0000] {standard_task_runner.py:90} INFO - Running: ['***', 'tasks', 'run', 'etl_pipeline', 'transform_data', 'manual__2025-08-19T19:56:32.538640+00:00', '--job-id', '3', '--raw', '--subdir', 'DAGS_FOLDER/etl_pipeline.py', '--cfg-path', '/tmp/tmpvdi67wag']
[2025-08-19T19:56:48.542+0000] {standard_task_runner.py:91} INFO - Job 3: Subtask transform_data
[2025-08-19T19:56:48.676+0000] {task_command.py:426} INFO - Running <TaskInstance: etl_pipeline.transform_data manual__2025-08-19T19:56:32.538640+00:00 [running]> on host a157d7c523bb
[2025-08-19T19:56:49.206+0000] {taskinstance.py:2648} INFO - Exporting env vars: AIRFLOW_CTX_DAG_OWNER='***' AIRFLOW_CTX_DAG_ID='etl_pipeline' AIRFLOW_CTX_TASK_ID='transform_data' AIRFLOW_CTX_EXECUTION_DATE='2025-08-19T19:56:32.538640+00:00' AIRFLOW_CTX_TRY_NUMBER='1' AIRFLOW_CTX_DAG_RUN_ID='manual__2025-08-19T19:56:32.538640+00:00'
[2025-08-19T19:56:49.208+0000] {taskinstance.py:430} INFO - ::endgroup::
[2025-08-19T19:56:50.509+0000] {taskinstance.py:441} INFO - ::group::Post task execution logs
[2025-08-19T19:56:50.512+0000] {taskinstance.py:2905} ERROR - Task failed with exception
Traceback (most recent call last):
  File "/home/airflow/.local/lib/python3.12/site-packages/airflow/models/taskinstance.py", line 465, in _execute_task
    result = _execute_callable(context=context, **execute_callable_kwargs)
             ^^^^^^^^^^^^^^^^^^^^^^^^^^^^^^^^^^^^^^^^^^^^^^^^^^^^^^^^^^^^^
  File "/home/airflow/.local/lib/python3.12/site-packages/airflow/models/taskinstance.py", line 432, in _execute_callable
    return execute_callable(context=context, **execute_callable_kwargs)
           ^^^^^^^^^^^^^^^^^^^^^^^^^^^^^^^^^^^^^^^^^^^^^^^^^^^^^^^^^^^^
  File "/home/airflow/.local/lib/python3.12/site-packages/airflow/models/baseoperator.py", line 401, in wrapper
    return func(self, *args, **kwargs)
           ^^^^^^^^^^^^^^^^^^^^^^^^^^^
  File "/home/airflow/.local/lib/python3.12/site-packages/airflow/operators/python.py", line 235, in execute
    return_value = self.execute_callable()
                   ^^^^^^^^^^^^^^^^^^^^^^^
  File "/home/airflow/.local/lib/python3.12/site-packages/airflow/operators/python.py", line 252, in execute_callable
    return self.python_callable(*self.op_args, **self.op_kwargs)
           ^^^^^^^^^^^^^^^^^^^^^^^^^^^^^^^^^^^^^^^^^^^^^^^^^^^^^
  File "/opt/airflow/dags/etl_pipeline.py", line 14, in transform_task
    transform_products()
  File "/opt/airflow/etl/transform_data.py", line 32, in transform_products
    os.makedirs(os.path.dirname(out_path), exist_ok=True)
  File "<frozen os>", line 225, in makedirs
PermissionError: [Errno 13] Permission denied: '../data'
[2025-08-19T19:56:51.542+0000] {taskinstance.py:1206} INFO - Marking task as FAILED. dag_id=etl_pipeline, task_id=transform_data, run_id=manual__2025-08-19T19:56:32.538640+00:00, execution_date=20250819T195632, start_date=20250819T195648, end_date=20250819T195651
[2025-08-19T19:56:51.619+0000] {standard_task_runner.py:110} ERROR - Failed to execute job 3 for task transform_data ([Errno 13] Permission denied: '../data'; 250)
[2025-08-19T19:56:51.696+0000] {local_task_job_runner.py:243} INFO - Task exited with return code 1
[2025-08-19T19:56:51.741+0000] {local_task_job_runner.py:222} INFO - ::endgroup::
